<robot name="waiteronix">
  <!-- This URDF was automatically created by SolidWorks to URDF Exporter! Originally created by Stephen Brawner (brawner@gmail.com) 
     Commit Version: 1.6.0-4-g7f85cfe  Build Version: 1.6.7995.38578
     For more information, please see http://wiki.ros.org/sw_urdf_exporter -->

  
  <link
    name="base_link">
    <inertial>
      <origin
        xyz="0.047332 6.6722E-08 0.43205"
        rpy="0 0 0" />
      <mass
        value="7.2595" />
      <inertia
        ixx="0.2352"
        ixy="-3.3315E-09"
        ixz="-0.0013775"
        iyy="0.23491"
        iyz="1.1095E-10"
        izz="0.18376" />
     </inertial>
     <visual>
      <origin
        xyz="0 0 0"
        rpy="0 0 0" />
      <geometry>
        <mesh
          filename="package://waiteronix/meshes/base_link.STL" />
      </geometry>
      <material
        name="">
        <color
          rgba="0.52941 0.54902 0.54902 1" />
      </material>
     </visual>
    <collision>
      <origin
        xyz="0 0 0"
        rpy="0 0 0" />
      <geometry>
        <mesh
          filename="package://waiteronix/meshes/base_link.STL" />
      </geometry>
    </collision>
  </link>
  
  <link
    name="Body">
    <inertial>
      <origin
        xyz="0.030377 8.5895E-16 0.11943"
        rpy="0 0 0" />
      <mass
        value="5.7583" />
      <inertia
        ixx="0.23029"
        ixy="-3.4648E-17"
        ixz="-0.0068726"
        iyy="0.17581"
        iyz="-2.2779E-17"
        izz="0.35786" />
    </inertial>
    <visual>
      <origin
        xyz="0 0 0"
        rpy="0 0 0" />
      <geometry>
        <mesh
          filename="package://waiteronix/meshes/Body.STL" />
      </geometry>
      <material
        name="">
        <color
          rgba="0.84706 0.84706 0.84706 1" />
      </material>
    </visual>
    <collision>
      <origin
        xyz="0 0 0"
        rpy="0 0 0" />
      <geometry>
        <mesh
          filename="package://waiteronix/meshes/Body.STL" />
      </geometry>
    </collision>
  </link>
  <joint
    name="Body_Joint"
    type="fixed">
    <origin
      xyz="0 0 0"
      rpy="0 0 0" />
    <parent
      link="base_link" />
    <child
      link="Body" />
    <axis
      xyz="0 0 0" />
  </joint>
  <link
    name="Right_Wheel">
    <inertial>
      <origin
        xyz="2.5996E-07 0.037854 6.57E-06"
        rpy="0 0 0" />
      <mass
        value="1.21" />
      <inertia
        ixx="0.0022228"
        ixy="-1.8762E-08"
        ixz="1.5736E-09"
        iyy="0.0036326"
        iyz="-4.7418E-07"
        izz="0.0022228" />
    </inertial>
    <visual>
      <origin
        xyz="0 0 0"
        rpy="0 0 0" />
      <geometry>
        <mesh
          filename="package://waiteronix/meshes/Right_Wheel.STL" />
      </geometry>
      <material
        name="">
        <color
          rgba="0.75294 0.75294 0.75294 1" />
      </material>
    </visual>
    <collision>
      <origin
        xyz="0 0 0"
        rpy="0 0 0" />
      <geometry>
        <mesh
          filename="package://waiteronix/meshes/Right_Wheel.STL" />
      </geometry>
    </collision>
  </link>
  <joint
    name="Right_Wheel_Joint"
    type="continuous">
    <origin
      xyz="-0.0087223 -0.224 0.054"
      rpy="0 0 0" />
    <parent
      link="base_link" />
    <child
      link="Right_Wheel" />
    <axis
      xyz="0 -1 0" />
    <limit
      effort="40"
      velocity="10" />
  </joint>
  <link
    name="Left_Wheel">
    <inertial>
      <origin
        xyz="2.5996E-07 -0.037854 6.57E-06"
        rpy="0 0 0" />
      <mass
        value="1.21" />
      <inertia
        ixx="0.0022228"
        ixy="1.8762E-08"
        ixz="1.5736E-09"
        iyy="0.0036326"
        iyz="4.7418E-07"
        izz="0.0022228" />
    </inertial>
    <visual>
      <origin
        xyz="0 0 0"
        rpy="0 0 0" />
      <geometry>
        <mesh
          filename="package://waiteronix/meshes/Left_Wheel.STL" />
      </geometry>
      <material
        name="">
        <color
          rgba="0.75294 0.75294 0.75294 1" />
      </material>
    </visual>
    <collision>
      <origin
        xyz="0 0 0"
        rpy="0 0 0" />
      <geometry>
        <mesh
          filename="package://waiteronix/meshes/Left_Wheel.STL" />
      </geometry>
    </collision>
  </link>
  <joint
    name="Left_Wheel_Joint"
    type="continuous">
    <origin
      xyz="-0.0087223 0.224 0.054"
      rpy="0 0 0" />
    <parent
      link="base_link" />
    <child
      link="Left_Wheel" />
    <axis
      xyz="0 -1 0" />
    <limit
      effort="40"
      velocity="10" />
  </joint>
  <link
    name="Camera">
    <inertial>
      <origin
        xyz="-0.027769 0.064365 -0.00028163"
        rpy="0 0 0" />
      <mass
        value="0.55893" />
      <inertia
        ixx="0.0029329"
        ixy="-9.3578E-07"
        ixz="8.9611E-08"
        iyy="0.00023177"
        iyz="-9.4508E-09"
        izz="0.0030272" />
    </inertial>
    <visual>
      <origin
        xyz="0 0 0"
        rpy="0 0 0" />
      <geometry>
        <mesh
          filename="package://waiteronix/meshes/Camera.STL" />
      </geometry>
      <material
        name="">
        <color
          rgba="0.49412 0.49412 0.49412 1" />
      </material>
    </visual>
    <collision>
      <origin
        xyz="0 0 0"
        rpy="0 0 0" />
      <geometry>
        <mesh
          filename="package://waiteronix/meshes/Camera.STL" />
      </geometry>
    </collision>
  </link>
  <joint
    name="Camera_Joint"
    type="fixed">
    <origin
      xyz="0.24478 -0.064307 0.0965"
      rpy="0 0 0" />
    <parent
      link="base_link" />
    <child
      link="Camera" />
    <axis
      xyz="1 0 0" />
  </joint>
  <link
    name="Lidar">
    <inertial>
      <origin
        xyz="8.3267E-17 -1.9976E-15 -0.013917"
        rpy="0 0 0" />
      <mass
        value="0.12331" />
      <inertia
        ixx="8.5672E-05"
        ixy="-3.3087E-22"
        ixz="-3.3193E-19"
        iyy="8.5672E-05"
        iyz="-1.4388E-23"
        izz="0.00010203" />
    </inertial>
    <visual>
      <origin
        xyz="0 0 0"
        rpy="0 0 0" />
      <geometry>
        <mesh
          filename="package://waiteronix/meshes/Lidar.STL" />
      </geometry>
      <material
        name="">
        <color
          rgba="0 0.75294 0 1" />
      </material>
    </visual>
    <collision>
      <origin
        xyz="0 0 0"
        rpy="0 0 0" />
      <geometry>
        <mesh
          filename="package://waiteronix/meshes/Lidar.STL" />
      </geometry>
    </collision>
  </link>
  <joint
    name="Lidar_Joint"
    type="fixed">
    <origin
      xyz="0.185 0 0.21663"
      rpy="0 0 0" />
    <parent
      link="base_link" />
    <child
      link="Lidar" />
    <axis
      xyz="0 0 1" />
  </joint>
  <link
    name="IMU">
    <inertial>
      <origin
        xyz="-1.8518E-16 -6.2326E-15 -0.005"
        rpy="0 0 0" />
      <mass
        value="0.0007854" />
      <inertia
        ixx="1.1454E-08"
        ixy="1.831E-25"
        ixz="-3.3736E-23"
        iyy="1.1454E-08"
        iyz="1.7323E-23"
        izz="9.8175E-09" />
    </inertial>
    <visual>
      <origin
        xyz="0 0 0"
        rpy="0 0 0" />
      <geometry>
        <mesh
          filename="package://waiteronix/meshes/IMU.STL" />
      </geometry>
      <material
        name="">
        <color
          rgba="0 0.75294 0 1" />
      </material>
    </visual>
    <collision>
      <origin
        xyz="0 0 0"
        rpy="0 0 0" />
      <geometry>
        <mesh
          filename="package://waiteronix/meshes/IMU.STL" />
      </geometry>
    </collision>
  </link>
  <joint
    name="IMU_Joint"
    type="fixed">
    <origin
      xyz="0 0 0.289"
      rpy="0 0 0" />
    <parent
      link="base_link" />
    <child
      link="IMU" />
    <axis
      xyz="0 0 1" />
  </joint>
  <link
    name="F_W_Front_Left">
    <inertial>
      <origin
        xyz="0.13868 0.123 -1.4438E-14"
        rpy="0 0 0" />
      <mass
        value="0.059636" />
      <inertia
        ixx="1.6012E-05"
        ixy="-1.927E-20"
        ixz="-9.0002E-22"
        iyy="2.7287E-05"
        iyz="-2.1253E-20"
        izz="1.6012E-05" />
    </inertial>
    <visual>
      <origin
        xyz="0 0 0"
        rpy="0 0 0" />
      <geometry>
        <mesh
          filename="package://waiteronix/meshes/F_W_Front_Left.STL" />
      </geometry>
      <material
        name="">
        <color
          rgba="0.50196 0.50196 1 1" />
      </material>
    </visual>
    <collision>
      <origin
        xyz="0 0 0"
        rpy="0 0 0" />
      <geometry>
        <mesh
          filename="package://waiteronix/meshes/F_W_Front_Left.STL" />
      </geometry>
    </collision>
  </link>
  <joint
    name="F_W_Front_Left_Joint"
    type="fixed">
    <origin
      xyz="0 0 0"
      rpy="0 0 0" />
    <parent
      link="base_link" />
    <child
      link="F_W_Front_Left" />
    <axis
      xyz="0 1 0" />
  </joint>
  <link
    name="F_W_Front_Right">
    <inertial>
      <origin
        xyz="0.13868 -0.123 2.4819E-14"
        rpy="0 0 0" />
      <mass
        value="0.059636" />
      <inertia
        ixx="1.6012E-05"
        ixy="5.4827E-21"
        ixz="-3.2336E-22"
        iyy="2.7287E-05"
        iyz="-3.8765E-20"
        izz="1.6012E-05" />
    </inertial>
    <visual>
      <origin
        xyz="0 0 0"
        rpy="0 0 0" />
      <geometry>
        <mesh
          filename="package://waiteronix/meshes/F_W_Front_Right.STL" />
      </geometry>
      <material
        name="">
        <color
          rgba="0.50196 0.50196 1 1" />
      </material>
    </visual>
    <collision>
      <origin
        xyz="0 0 0"
        rpy="0 0 0" />
      <geometry>
        <mesh
          filename="package://waiteronix/meshes/F_W_Front_Right.STL" />
      </geometry>
    </collision>
  </link>
  <joint
    name="F_W_Front_Right_Joint"
    type="fixed">
    <origin
      xyz="0 0 0"
      rpy="0 0 0" />
    <parent
      link="base_link" />
    <child
      link="F_W_Front_Right" />
    <axis
      xyz="0 1 0" />
  </joint>
  <link
    name="F_W_Back_Left">
    <inertial>
      <origin
        xyz="-0.19 0.1215 -1.622E-14"
        rpy="0 0 0" />
      <mass
        value="0.059636" />
      <inertia
        ixx="1.6012E-05"
        ixy="2.3169E-21"
        ixz="-1.6362E-21"
        iyy="2.7287E-05"
        iyz="-4.46E-21"
        izz="1.6012E-05" />
    </inertial>
    <visual>
      <origin
        xyz="0 0 0"
        rpy="0 0 0" />
      <geometry>
        <mesh
          filename="package://waiteronix/meshes/F_W_Back_Left.STL" />
      </geometry>
      <material
        name="">
        <color
          rgba="0.50196 0.50196 1 1" />
      </material>
    </visual>
    <collision>
      <origin
        xyz="0 0 0"
        rpy="0 0 0" />
      <geometry>
        <mesh
          filename="package://waiteronix/meshes/F_W_Back_Left.STL" />
      </geometry>
    </collision>
  </link>
  <joint
    name="F_W_Back_Left_Joint"
    type="fixed">
    <origin
      xyz="0 0 0"
      rpy="0 0 0" />
    <parent
      link="base_link" />
    <child
      link="F_W_Back_Left" />
    <axis
      xyz="0 1 0" />
  </joint>
  <link
    name="F_W_Back_Right">
    <inertial>
      <origin
        xyz="-0.19 -0.1215 -1.6079E-14"
        rpy="0 0 0" />
      <mass
        value="0.059636" />
      <inertia
        ixx="1.6012E-05"
        ixy="2.9984E-21"
        ixz="-1.6638E-21"
        iyy="2.7287E-05"
        iyz="-1.7395E-22"
        izz="1.6012E-05" />
    </inertial>
    <visual>
      <origin
        xyz="0 0 0"
        rpy="0 0 0" />
      <geometry>
        <mesh
          filename="package://waiteronix/meshes/F_W_Back_Right.STL" />
      </geometry>
      <material
        name="">
        <color
          rgba="0.50196 0.50196 1 1" />
      </material>
    </visual>
    <collision>
      <origin
        xyz="0 0 0"
        rpy="0 0 0" />
      <geometry>
        <mesh
          filename="package://waiteronix/meshes/F_W_Back_Right.STL" />
      </geometry>
    </collision>
  </link>
  <joint
    name="F_W_Back_Right_Joint"
    type="fixed">
    <origin
      xyz="0 0 0"
      rpy="0 0 0" />
    <parent
      link="base_link" />
    <child
      link="F_W_Back_Right" />
    <axis
      xyz="0 1 0" />
  </joint>
  <gazebo reference="Camera">
  <sensor name="Camera_camera" type="depth">
    <update_rate>20</update_rate>
    <camera>
      <horizontal_fov>1.047198</horizontal_fov>
      <image>
        <width>640</width>
        <height>480</height>
        <format>R8G8B8</format>
      </image>
      <clip>
        <near>0.05</near>
        <far>3</far>
      </clip>
    </camera>
    <plugin name="Camera_controller" filename="libgazebo_ros_openni_kinect.so">
      <baseline>0.2</baseline>
      <alwaysOn>true</alwaysOn>
      <updateRate>1.0</updateRate>
      <cameraName>Camera_ir</cameraName>
      <imageTopicName>/Camera/color/image_raw</imageTopicName>
      <cameraInfoTopicName>/Camera/color/camera_info</cameraInfoTopicName>
      <depthImageTopicName>/Camera/depth/image_raw</depthImageTopicName>
      <depthImageInfoTopicName>/Camera/depth/camera_info</depthImageInfoTopicName>
      <pointCloudTopicName>/Camera/depth/points</pointCloudTopicName>
      <frameName>camera_link</frameName>
      <pointCloudCutoff>0.5</pointCloudCutoff>
      <pointCloudCutoffMax>3.0</pointCloudCutoffMax>
      <distortionK1>0.00000001</distortionK1>
      <distortionK2>0.00000001</distortionK2>
      <distortionK3>0.00000001</distortionK3>
      <distortionT1>0.00000001</distortionT1>
      <distortionT2>0.00000001</distortionT2>
      <CxPrime>0</CxPrime>
      <Cx>0</Cx>
      <Cy>0</Cy>
      <focalLength>0</focalLength>
      <hackBaseline>0</hackBaseline>
    </plugin>
  </sensor>
   </gazebo>
    <gazebo reference="Lidar">
        <sensor type="ray" name="laser" >
            <pose> 0 0 0 0 0 0 </pose>
            <visualize>true</visualize>
            <update_rate>10</update_rate>
            <ray>
                <scan>
                    <horizontal>
                        <samples>360</samples>
                        <min_angle>-3.14</min_angle>
                        <max_angle>3.14</max_angle>
                    </horizontal>
                </scan>
                <range>
                    <min>0.3</min>
                    <max>12</max>
                </range>
            </ray>
            <plugin name="Lidar_controller" filename="libgazebo_ros_ray_sensor.so">
                 <topicName>/scan</topicName>
                <frame_name>Lidar</frame_name>
            </plugin>
        </sensor>
    </gazebo>
    
 
  
</robot>